<mujoco model="robot_assy">
  <option iterations="50" timestep="0.001" solver="PGS" gravity="0 0 -9.81" />

  <compiler angle="radian" meshdir="meshes" eulerseq="zyx" autolimits="true" />

  <default>
    <joint limited="true" damping="0.01" armature="0.01" frictionloss="0.01" />
    <geom condim="4" contype="1" conaffinity="15" friction="0.9 0.2 0.2" solref="0.001 2" />
    <motor ctrllimited="true" />
    <equality solref="0.001 2" />
    <default class="visualgeom">
      <geom material="visualgeom" condim="1" contype="0" conaffinity="0" />
    </default>
  </default>

  <asset>
    <mesh name="KB-B-102B_TORSO_BOTTOM" file="KB-B-102B_TORSO_BOTTOM.stl" />
    <mesh name="KB-D-102R_R_Hip_Yoke_Drive" file="KB-D-102R_R_Hip_Yoke_Drive.stl" />
    <mesh name="KB-D-102L_L_Hip_Yoke_Drive" file="KB-D-102L_L_Hip_Yoke_Drive.stl" />
    <mesh name="KB-C-101R_R_Shoulder_Drive" file="KB-C-101R_R_Shoulder_Drive.stl" />
    <mesh name="KB-C-101L_ShldYokeROLL" file="KB-C-101L_ShldYokeROLL.stl" />
    <mesh name="RS03" file="RS03.stl" />
    <mesh name="RS03_2" file="RS03_2.stl" />
    <mesh name="RS03_3" file="RS03_3.stl" />
    <mesh name="RS03_4" file="RS03_4.stl" />
    <mesh name="KB-D-301L_L_Femur_Lower_Drive" file="KB-D-301L_L_Femur_Lower_Drive.stl" />
    <mesh name="R_Bicep_Lower_Drive" file="R_Bicep_Lower_Drive.stl" />
    <mesh name="KB-D-301R_R_Femur_Lower_Drive" file="KB-D-301R_R_Femur_Lower_Drive.stl" />
    <mesh name="L_Bicep_Lower_Drive" file="L_Bicep_Lower_Drive.stl" />
    <mesh name="KB-D-401L_L_Shin_Drive" file="KB-D-401L_L_Shin_Drive.stl" />
    <mesh name="R_Forearm_Upper_Structural" file="R_Forearm_Upper_Structural.stl" />
    <mesh name="KB-D-501L_L_LEG-FOOT" file="KB-D-501L_L_LEG-FOOT.stl" />
    <mesh name="KB-D-401R_R_Shin_Drive" file="KB-D-401R_R_Shin_Drive.stl" />
    <mesh name="L_Forearm_Upper_Drive" file="L_Forearm_Upper_Drive.stl" />
    <mesh name="KB-D-501R_R_LEG-FOOT" file="KB-D-501R_R_LEG-FOOT.stl" />
    <mesh name="KB-C-501X_Bayonet_Adapter_Hard_Stop" file="KB-C-501X_Bayonet_Adapter_Hard_Stop.stl" />
    <mesh name="KB-C-501X_Bayonet_Adapter_Hard_Stop_2" file="KB-C-501X_Bayonet_Adapter_Hard_Stop_2.stl" />
    <texture name="texplane" type="2d" builtin="checker" rgb1=".0 .0 .0" rgb2=".8 .8 .8" width="100" height="100" />
    <material name="matplane" reflectance="0." texture="texplane" texrepeat="1 1" texuniform="true" />
    <material name="visualgeom" rgba="0.5 0.9 0.2 1" />
  </asset>

  <worldbody>
    <light directional="true" diffuse="0.4 0.4 0.4" specular="0.1 0.1 0.1" pos="0 0 5.0" dir="0 0 -1" castshadow="false" />
    <light directional="true" diffuse="0.6 0.6 0.6" specular="0.2 0.2 0.2" pos="0 0 4" dir="0 0 -1" />
    <geom name="ground" type="plane" pos="0 0 0" size="100 100 0.001" quat="1 0 0 0" material="matplane" condim="3" conaffinity="15" />
    <camera name="fixed" pos="0 -3.0 0.5" xyaxes="1 0 0 0 0 1" />
    <camera name="track" mode="trackcom" pos="0 -3.0 0.5" xyaxes="1 0 0 0 0 1" />
    <body name="root" pos="0 0 0.01" quat="1 0 0 0">
      <freejoint name="root" />
      <site name="imu" size="0.01" pos="0 0 0" />
      <geom type="mesh" rgba="0.615686 0.811765 0.929412 1" mesh="KB-B-102B_TORSO_BOTTOM" contype="1" conaffinity="0" density="0" group="1" class="visualgeom" />
      <geom type="mesh" rgba="0.615686 0.811765 0.929412 1" mesh="KB-B-102B_TORSO_BOTTOM" />
      <body name="KB-D-102R_R_Hip_Yoke_Drive" pos="0.047048 -0.000737259 -0.0729935" quat="0.5 0.5 -0.5 -0.5">
        <inertial pos="-0.00518705 -0.00237372 -0.0391575" quat="-0.395694 0.566905 0.00397172 0.722516" mass="0.710534" diaginertia="0.00190819 0.00146086 0.00119488" />
        <joint name="right_hip_pitch_04" pos="0 0 0" axis="0 0 1" range="-1.91986 1.5708" actuatorfrcrange="-80 80" />
        <geom type="mesh" rgba="0.262745 0.282353 0.301961 1" mesh="KB-D-102R_R_Hip_Yoke_Drive" contype="1" conaffinity="0" density="0" group="1" class="visualgeom" />
        <geom type="mesh" rgba="0.262745 0.282353 0.301961 1" mesh="KB-D-102R_R_Hip_Yoke_Drive" />
        <body name="RS03" pos="-0.02925 -0.03 -0.071" quat="0.707107 0 -0.707107 0">
          <inertial pos="-0.00067719 -0.0582557 -0.0282885" quat="0.49968 0.502022 -0.504248 0.493992" mass="2.59032" diaginertia="0.0115811 0.0110638 0.00380208" />
          <joint name="right_hip_roll_03" pos="0 0 0" axis="0 0 1" range="-2.61799 0.20944" actuatorfrcrange="-80 80" />
          <geom type="mesh" rgba="0.615686 0.811765 0.929412 1" mesh="RS03" contype="1" conaffinity="0" density="0" group="1" class="visualgeom" />
          <geom type="mesh" rgba="0.615686 0.811765 0.929412 1" mesh="RS03" />
          <body name="KB-D-301L_L_Femur_Lower_Drive" pos="0 -0.14175 -0.0298" quat="0.707107 -0.707107 0 0">
            <inertial pos="-0.000138526 0.0105108 -0.162476" quat="0.995842 0.0773442 -0.0449612 -0.0171919" mass="2.55677" diaginertia="0.0181434 0.0166515 0.00432563" />
            <joint name="right_hip_yaw_03" pos="0 0 0" axis="0 0 1" range="-1.5708 1.91986" actuatorfrcrange="-80 80" />
            <geom type="mesh" rgba="0.439216 0.47451 0.501961 1" mesh="KB-D-301L_L_Femur_Lower_Drive" contype="1" conaffinity="0" density="0" group="1" class="visualgeom" />
            <geom type="mesh" rgba="0.439216 0.47451 0.501961 1" mesh="KB-D-301L_L_Femur_Lower_Drive" />
            <body name="KB-D-401L_L_Shin_Drive" pos="-0.0196 0.021 -0.212" quat="0.5 0.5 0.5 0.5">
              <inertial pos="-0.0261276 -0.0975927 0.0201948" quat="0.712741 0.698136 0.0365784 -0.0571758" mass="2.0621" diaginertia="0.0181457 0.0178723 0.00377024" />
              <joint name="right_knee_04" pos="0 0 0" axis="0 0 1" range="0 2.67035" actuatorfrcrange="-80 80" />
              <geom type="mesh" rgba="0.34902 0.376471 0.4 1" mesh="KB-D-401L_L_Shin_Drive" contype="1" conaffinity="0" density="0" group="1" class="visualgeom" />
              <geom type="mesh" rgba="0.34902 0.376471 0.4 1" mesh="KB-D-401L_L_Shin_Drive" />
              <body name="KB-D-501L_L_LEG-FOOT" pos="-0.0313 -0.2925 0.005">
                <inertial pos="-0.0132646 -0.0285779 0.0119443" quat="0.425323 0.53702 0.470051 0.556563" mass="0.492748" diaginertia="0.00156934 0.00148223 0.000277396" />
                <joint name="right_ankle_02" pos="0 0 0" axis="0 0 -1" range="-0.296706 0.785398" actuatorfrcrange="-80 80" />
                <geom type="mesh" rgba="0.972549 0.529412 0.00392157 1" mesh="KB-D-501L_L_LEG-FOOT" contype="1" conaffinity="0" density="0" group="1" class="visualgeom" />
                <geom type="mesh" rgba="0.972549 0.529412 0.00392157 1" mesh="KB-D-501L_L_LEG-FOOT" />
              </body>
            </body>
          </body>
        </body>
      </body>
      <body name="KB-D-102L_L_Hip_Yoke_Drive" pos="-0.047048 -0.000737257 -0.0729935" quat="0.5 -0.5 0.5 -0.5">
        <inertial pos="-0.00526924 0.00243321 -0.0391574" quat="0.398842 0.563025 -0.0105267 0.723752" mass="0.710534" diaginertia="0.00190529 0.00145789 0.00119359" />
        <joint name="left_hip_pitch_04" pos="0 0 0" axis="0 0 1" range="-1.5708 1.91986" actuatorfrcrange="-80 80" />
        <geom type="mesh" rgba="0.262745 0.282353 0.301961 1" mesh="KB-D-102L_L_Hip_Yoke_Drive" contype="1" conaffinity="0" density="0" group="1" class="visualgeom" />
        <geom type="mesh" rgba="0.262745 0.282353 0.301961 1" mesh="KB-D-102L_L_Hip_Yoke_Drive" />
        <body name="RS03_2" pos="-0.02925 0.03 -0.071" quat="-1.64085e-08 0.707107 -1.64085e-08 -0.707107">
          <inertial pos="0.00067678 -0.0582571 -0.0282895" quat="0.494046 0.504303 -0.501971 0.499622" mass="2.59043" diaginertia="0.0115813 0.0110642 0.00380245" />
          <joint name="left_hip_roll_03" pos="0 0 0" axis="0 0 1" range="-0.20944 2.61799" actuatorfrcrange="-80 80" />
          <geom type="mesh" rgba="0.615686 0.811765 0.929412 1" mesh="RS03_2" contype="1" conaffinity="0" density="0" group="1" class="visualgeom" />
          <geom type="mesh" rgba="0.615686 0.811765 0.929412 1" mesh="RS03_2" />
          <body name="KB-D-301R_R_Femur_Lower_Drive" pos="0 -0.14175 -0.0298" quat="0.707107 -0.707107 0 0">
            <inertial pos="0.000138587 0.0105112 -0.162474" quat="0.995842 0.0773383 0.0449574 0.0172221" mass="2.55683" diaginertia="0.0181442 0.0166524 0.00432586" />
            <joint name="left_hip_yaw_03" pos="0 0 0" axis="0 0 1" range="-1.5708 1.91986" actuatorfrcrange="-80 80" />
            <geom type="mesh" rgba="0.439216 0.47451 0.501961 1" mesh="KB-D-301R_R_Femur_Lower_Drive" contype="1" conaffinity="0" density="0" group="1" class="visualgeom" />
            <geom type="mesh" rgba="0.439216 0.47451 0.501961 1" mesh="KB-D-301R_R_Femur_Lower_Drive" />
            <body name="KB-D-401R_R_Shin_Drive" pos="0.0196 0.021 -0.212" quat="0.5 -0.5 -0.5 0.5">
              <inertial pos="-0.0262711 0.0975895 0.0204625" quat="0.698387 0.713003 0.0538058 -0.0314237" mass="2.06224" diaginertia="0.0181774 0.017856 0.00378002" />
              <joint name="left_knee_04" pos="0 0 0" axis="0 0 1" range="-2.67035 0" actuatorfrcrange="-80 80" />
              <geom type="mesh" rgba="0.34902 0.376471 0.4 1" mesh="KB-D-401R_R_Shin_Drive" contype="1" conaffinity="0" density="0" group="1" class="visualgeom" />
              <geom type="mesh" rgba="0.34902 0.376471 0.4 1" mesh="KB-D-401R_R_Shin_Drive" />
              <body name="KB-D-501R_R_LEG-FOOT" pos="-0.0313 0.2925 0.005" quat="-2.32051e-08 1 0 0">
                <inertial pos="-0.0132646 -0.0285779 -0.0119443" quat="0.53702 0.425323 0.556563 0.470051" mass="0.492747" diaginertia="0.00156934 0.00148223 0.000277396" />
                <joint name="left_ankle_02" pos="0 0 0" axis="0 0 1" range="-0.296706 0.785398" actuatorfrcrange="-80 80" />
                <geom type="mesh" rgba="0.972549 0.529412 0.00392157 1" mesh="KB-D-501R_R_LEG-FOOT" contype="1" conaffinity="0" density="0" group="1" class="visualgeom" />
                <geom type="mesh" rgba="0.972549 0.529412 0.00392157 1" mesh="KB-D-501R_R_LEG-FOOT" />
              </body>
            </body>
          </body>
        </body>
      </body>
      <body name="KB-C-101R_R_Shoulder_Drive" pos="0.12495 -0.000737261 0.337507" quat="0.5 0.5 -0.5 -0.5">
        <inertial pos="-0.00496284 0.00334441 -0.0445282" quat="0.590219 0.393242 0.545702 0.446332" mass="0.545077" diaginertia="0.00138635 0.00117231 0.000944142" />
        <joint name="left_shoulder_pitch_03" pos="0 0 0" axis="0 0 1" range="-1.91986 3.49066" actuatorfrcrange="-80 80" />
        <geom type="mesh" rgba="0.615686 0.811765 0.929412 1" mesh="KB-C-101R_R_Shoulder_Drive" contype="1" conaffinity="0" density="0" group="1" class="visualgeom" />
        <geom type="mesh" rgba="0.615686 0.811765 0.929412 1" mesh="KB-C-101R_R_Shoulder_Drive" />
        <body name="RS03_3" pos="-0.02525 0 -0.075" quat="0.707107 0 -0.707107 0">
          <inertial pos="-0.00553354 -0.044204 -0.0297113" quat="0.52809 0.471291 -0.531324 0.465511" mass="1.86143" diaginertia="0.00823598 0.00777473 0.00204396" />
          <joint name="left_shoulder_roll_03" pos="0 0 0" axis="0 0 1" range="-1.48353 0.488692" actuatorfrcrange="-80 80" />
          <geom type="mesh" rgba="0.615686 0.811765 0.929412 1" mesh="RS03_3" contype="1" conaffinity="0" density="0" group="1" class="visualgeom" />
          <geom type="mesh" rgba="0.615686 0.811765 0.929412 1" mesh="RS03_3" />
          <body name="R_Bicep_Lower_Drive" pos="-0.013 -0.141 -0.0302502" quat="0.707107 -0.707107 0 0">
            <inertial pos="0.00174116 -0.00312809 -0.0961052" quat="0.998065 -0.0428951 0.0444119 -0.00727027" mass="0.863923" diaginertia="0.00302076 0.002803 0.000862969" />
            <joint name="left_shoulder_yaw_02" pos="0 0 0" axis="0 0 1" range="-1.74533 1.74533" actuatorfrcrange="-80 80" />
            <geom type="mesh" rgba="0.764706 0.545098 0.803922 1" mesh="R_Bicep_Lower_Drive" contype="1" conaffinity="0" density="0" group="1" class="visualgeom" />
            <geom type="mesh" rgba="0.764706 0.545098 0.803922 1" mesh="R_Bicep_Lower_Drive" />
            <body name="R_Forearm_Upper_Structural" pos="0.0175 -0.01 -0.137" quat="0.5 -0.5 -0.5 0.5">
              <inertial pos="0.0160903 0.0590489 0.0144697" quat="0.622902 0.709651 0.222019 -0.243098" mass="0.67694" diaginertia="0.00140509 0.00138273 0.000678509" />
              <joint name="left_elbow_02" pos="0 0 0" axis="0 0 1" range="0 2.53073" actuatorfrcrange="-80 80" />
              <geom type="mesh" rgba="0.615686 0.811765 0.929412 1" mesh="R_Forearm_Upper_Structural" contype="1" conaffinity="0" density="0" group="1" class="visualgeom" />
              <geom type="mesh" rgba="0.615686 0.811765 0.929412 1" mesh="R_Forearm_Upper_Structural" />
              <body name="KB-C-501X_Bayonet_Adapter_Hard_Stop" pos="0.01735 0.1055 0.018" quat="0.5 0.5 0.5 -0.5">
                <inertial pos="-0.00257119 3.50738e-06 -0.0393706" quat="0.999406 -0.00102682 0.0344309 -0.000738314" mass="0.571799" diaginertia="0.000750674 0.000720096 0.000580472" />
                <joint name="left_wrist_02" pos="0 0 0" axis="0 0 1" range="-1.74533 1.74533" actuatorfrcrange="-80 80" />
                <geom type="mesh" rgba="0.917647 0.917647 0.917647 1" mesh="KB-C-501X_Bayonet_Adapter_Hard_Stop" contype="1" conaffinity="0" density="0" group="1" class="visualgeom" />
                <geom type="mesh" rgba="0.917647 0.917647 0.917647 1" mesh="KB-C-501X_Bayonet_Adapter_Hard_Stop" />
              </body>
            </body>
          </body>
        </body>
      </body>
      <body name="KB-C-101L_ShldYokeROLL" pos="-0.12495 -0.000737256 0.337507" quat="0.5 -0.5 -0.5 0.5">
        <inertial pos="0.00518945 -0.00334428 0.0445274" quat="0.595797 0.385204 0.539419 0.45351" mass="0.545099" diaginertia="0.00137432 0.00116155 0.000942909" />
        <joint name="right_shoulder_pitch_03" pos="0 0 0" axis="0 0 -1" range="-1.91986 3.49066" actuatorfrcrange="-80 80" />
        <geom type="mesh" rgba="0.615686 0.811765 0.929412 1" mesh="KB-C-101L_ShldYokeROLL" contype="1" conaffinity="0" density="0" group="1" class="visualgeom" />
        <geom type="mesh" rgba="0.615686 0.811765 0.929412 1" mesh="KB-C-101L_ShldYokeROLL" />
        <body name="RS03_4" pos="0.02525 0 0.075" quat="-1.64085e-08 0.707107 1.64085e-08 0.707107">
          <inertial pos="0.00553364 -0.0442196 -0.0297116" quat="0.4655 0.531351 -0.471257 0.528103" mass="1.86146" diaginertia="0.00824155 0.00778052 0.0020438" />
          <joint name="right_shoulder_roll_03" pos="0 0 0" axis="0 0 1" range="-0.488692 1.48353" actuatorfrcrange="-80 80" />
          <geom type="mesh" rgba="0.615686 0.811765 0.929412 1" mesh="RS03_4" contype="1" conaffinity="0" density="0" group="1" class="visualgeom" />
          <geom type="mesh" rgba="0.615686 0.811765 0.929412 1" mesh="RS03_4" />
          <body name="L_Bicep_Lower_Drive" pos="0.013 -0.141 -0.0302502" quat="0.707107 -0.707107 0 0">
            <inertial pos="-0.00172376 -0.00312338 -0.0960877" quat="0.998073 -0.0429053 -0.0442889 0.00694271" mass="0.864297" diaginertia="0.0030215 0.00280439 0.000863807" />
            <joint name="right_shoulder_yaw_02" pos="0 0 0" axis="0 0 1" range="-1.74533 1.74533" actuatorfrcrange="-80 80" />
            <geom type="mesh" rgba="0.764706 0.545098 0.803922 1" mesh="L_Bicep_Lower_Drive" contype="1" conaffinity="0" density="0" group="1" class="visualgeom" />
            <geom type="mesh" rgba="0.764706 0.545098 0.803922 1" mesh="L_Bicep_Lower_Drive" />
            <body name="L_Forearm_Upper_Drive" pos="-0.0175 -0.01 -0.137" quat="0.5 0.5 0.5 0.5">
              <inertial pos="0.0160893 -0.0590493 0.0144693" quat="0.70963 0.622865 0.243183 -0.222094" mass="0.676937" diaginertia="0.00140505 0.00138276 0.000678509" />
              <joint name="right_elbow_02" pos="0 0 0" axis="0 0 1" range="-2.53073 0" actuatorfrcrange="-80 80" />
              <geom type="mesh" rgba="0.615686 0.811765 0.929412 1" mesh="L_Forearm_Upper_Drive" contype="1" conaffinity="0" density="0" group="1" class="visualgeom" />
              <geom type="mesh" rgba="0.615686 0.811765 0.929412 1" mesh="L_Forearm_Upper_Drive" />
              <body name="KB-C-501X_Bayonet_Adapter_Hard_Stop_2" pos="0.01735 -0.1055 0.018" quat="0.5 0.5 -0.5 0.5">
                <inertial pos="0.00257119 3.50757e-06 0.0393706" quat="0.999406 0.0010268 0.0344309 0.00073833" mass="0.571799" diaginertia="0.000750674 0.000720096 0.000580472" />
                <joint name="right_wrist_02" pos="0 0 0" axis="0 0 -1" range="-1.74533 1.74533" actuatorfrcrange="-80 80" />
                <geom type="mesh" rgba="0.917647 0.917647 0.917647 1" mesh="KB-C-501X_Bayonet_Adapter_Hard_Stop_2" contype="1" conaffinity="0" density="0" group="1" class="visualgeom" />
                <geom type="mesh" rgba="0.917647 0.917647 0.917647 1" mesh="KB-C-501X_Bayonet_Adapter_Hard_Stop_2" />
              </body>
            </body>
          </body>
        </body>
      </body>
    </body>
  </worldbody>

  <actuator>
    <motor name="right_hip_pitch_04" joint="right_hip_pitch_04" ctrllimited="true" ctrlrange="-80 80" gear="1" />
    <motor name="right_hip_roll_03" joint="right_hip_roll_03" ctrllimited="true" ctrlrange="-80 80" gear="1" />
    <motor name="right_hip_yaw_03" joint="right_hip_yaw_03" ctrllimited="true" ctrlrange="-80 80" gear="1" />
    <motor name="right_knee_04" joint="right_knee_04" ctrllimited="true" ctrlrange="-80 80" gear="1" />
    <motor name="right_ankle_02" joint="right_ankle_02" ctrllimited="true" ctrlrange="-80 80" gear="1" />
    <motor name="left_hip_pitch_04" joint="left_hip_pitch_04" ctrllimited="true" ctrlrange="-80 80" gear="1" />
    <motor name="left_hip_roll_03" joint="left_hip_roll_03" ctrllimited="true" ctrlrange="-80 80" gear="1" />
    <motor name="left_hip_yaw_03" joint="left_hip_yaw_03" ctrllimited="true" ctrlrange="-80 80" gear="1" />
    <motor name="left_knee_04" joint="left_knee_04" ctrllimited="true" ctrlrange="-80 80" gear="1" />
    <motor name="left_ankle_02" joint="left_ankle_02" ctrllimited="true" ctrlrange="-80 80" gear="1" />
    <motor name="left_shoulder_pitch_03" joint="left_shoulder_pitch_03" ctrllimited="true" ctrlrange="-80 80" gear="1" />
    <motor name="left_shoulder_roll_03" joint="left_shoulder_roll_03" ctrllimited="true" ctrlrange="-80 80" gear="1" />
    <motor name="left_shoulder_yaw_02" joint="left_shoulder_yaw_02" ctrllimited="true" ctrlrange="-80 80" gear="1" />
    <motor name="left_elbow_02" joint="left_elbow_02" ctrllimited="true" ctrlrange="-80 80" gear="1" />
    <motor name="left_wrist_02" joint="left_wrist_02" ctrllimited="true" ctrlrange="-80 80" gear="1" />
    <motor name="right_shoulder_pitch_03" joint="right_shoulder_pitch_03" ctrllimited="true" ctrlrange="-80 80" gear="1" />
    <motor name="right_shoulder_roll_03" joint="right_shoulder_roll_03" ctrllimited="true" ctrlrange="-80 80" gear="1" />
    <motor name="right_shoulder_yaw_02" joint="right_shoulder_yaw_02" ctrllimited="true" ctrlrange="-80 80" gear="1" />
    <motor name="right_elbow_02" joint="right_elbow_02" ctrllimited="true" ctrlrange="-80 80" gear="1" />
    <motor name="right_wrist_02" joint="right_wrist_02" ctrllimited="true" ctrlrange="-80 80" gear="1" />
  </actuator>

  <sensor>
    <actuatorpos name="right_hip_pitch_04_p" actuator="right_hip_pitch_04" />
    <actuatorvel name="right_hip_pitch_04_v" actuator="right_hip_pitch_04" />
    <actuatorfrc name="right_hip_pitch_04_f" actuator="right_hip_pitch_04" noise="0.001" />
    <actuatorpos name="right_hip_roll_03_p" actuator="right_hip_roll_03" />
    <actuatorvel name="right_hip_roll_03_v" actuator="right_hip_roll_03" />
    <actuatorfrc name="right_hip_roll_03_f" actuator="right_hip_roll_03" noise="0.001" />
    <actuatorpos name="right_hip_yaw_03_p" actuator="right_hip_yaw_03" />
    <actuatorvel name="right_hip_yaw_03_v" actuator="right_hip_yaw_03" />
    <actuatorfrc name="right_hip_yaw_03_f" actuator="right_hip_yaw_03" noise="0.001" />
    <actuatorpos name="right_knee_04_p" actuator="right_knee_04" />
    <actuatorvel name="right_knee_04_v" actuator="right_knee_04" />
    <actuatorfrc name="right_knee_04_f" actuator="right_knee_04" noise="0.001" />
    <actuatorpos name="right_ankle_02_p" actuator="right_ankle_02" />
    <actuatorvel name="right_ankle_02_v" actuator="right_ankle_02" />
    <actuatorfrc name="right_ankle_02_f" actuator="right_ankle_02" noise="0.001" />
    <actuatorpos name="left_hip_pitch_04_p" actuator="left_hip_pitch_04" />
    <actuatorvel name="left_hip_pitch_04_v" actuator="left_hip_pitch_04" />
    <actuatorfrc name="left_hip_pitch_04_f" actuator="left_hip_pitch_04" noise="0.001" />
    <actuatorpos name="left_hip_roll_03_p" actuator="left_hip_roll_03" />
    <actuatorvel name="left_hip_roll_03_v" actuator="left_hip_roll_03" />
    <actuatorfrc name="left_hip_roll_03_f" actuator="left_hip_roll_03" noise="0.001" />
    <actuatorpos name="left_hip_yaw_03_p" actuator="left_hip_yaw_03" />
    <actuatorvel name="left_hip_yaw_03_v" actuator="left_hip_yaw_03" />
    <actuatorfrc name="left_hip_yaw_03_f" actuator="left_hip_yaw_03" noise="0.001" />
    <actuatorpos name="left_knee_04_p" actuator="left_knee_04" />
    <actuatorvel name="left_knee_04_v" actuator="left_knee_04" />
    <actuatorfrc name="left_knee_04_f" actuator="left_knee_04" noise="0.001" />
    <actuatorpos name="left_ankle_02_p" actuator="left_ankle_02" />
    <actuatorvel name="left_ankle_02_v" actuator="left_ankle_02" />
    <actuatorfrc name="left_ankle_02_f" actuator="left_ankle_02" noise="0.001" />
    <actuatorpos name="left_shoulder_pitch_03_p" actuator="left_shoulder_pitch_03" />
    <actuatorvel name="left_shoulder_pitch_03_v" actuator="left_shoulder_pitch_03" />
    <actuatorfrc name="left_shoulder_pitch_03_f" actuator="left_shoulder_pitch_03" noise="0.001" />
    <actuatorpos name="left_shoulder_roll_03_p" actuator="left_shoulder_roll_03" />
    <actuatorvel name="left_shoulder_roll_03_v" actuator="left_shoulder_roll_03" />
    <actuatorfrc name="left_shoulder_roll_03_f" actuator="left_shoulder_roll_03" noise="0.001" />
    <actuatorpos name="left_shoulder_yaw_02_p" actuator="left_shoulder_yaw_02" />
    <actuatorvel name="left_shoulder_yaw_02_v" actuator="left_shoulder_yaw_02" />
    <actuatorfrc name="left_shoulder_yaw_02_f" actuator="left_shoulder_yaw_02" noise="0.001" />
    <actuatorpos name="left_elbow_02_p" actuator="left_elbow_02" />
    <actuatorvel name="left_elbow_02_v" actuator="left_elbow_02" />
    <actuatorfrc name="left_elbow_02_f" actuator="left_elbow_02" noise="0.001" />
    <actuatorpos name="left_wrist_02_p" actuator="left_wrist_02" />
    <actuatorvel name="left_wrist_02_v" actuator="left_wrist_02" />
    <actuatorfrc name="left_wrist_02_f" actuator="left_wrist_02" noise="0.001" />
    <actuatorpos name="right_shoulder_pitch_03_p" actuator="right_shoulder_pitch_03" />
    <actuatorvel name="right_shoulder_pitch_03_v" actuator="right_shoulder_pitch_03" />
    <actuatorfrc name="right_shoulder_pitch_03_f" actuator="right_shoulder_pitch_03" noise="0.001" />
    <actuatorpos name="right_shoulder_roll_03_p" actuator="right_shoulder_roll_03" />
    <actuatorvel name="right_shoulder_roll_03_v" actuator="right_shoulder_roll_03" />
    <actuatorfrc name="right_shoulder_roll_03_f" actuator="right_shoulder_roll_03" noise="0.001" />
    <actuatorpos name="right_shoulder_yaw_02_p" actuator="right_shoulder_yaw_02" />
    <actuatorvel name="right_shoulder_yaw_02_v" actuator="right_shoulder_yaw_02" />
    <actuatorfrc name="right_shoulder_yaw_02_f" actuator="right_shoulder_yaw_02" noise="0.001" />
    <actuatorpos name="right_elbow_02_p" actuator="right_elbow_02" />
    <actuatorvel name="right_elbow_02_v" actuator="right_elbow_02" />
    <actuatorfrc name="right_elbow_02_f" actuator="right_elbow_02" noise="0.001" />
    <actuatorpos name="right_wrist_02_p" actuator="right_wrist_02" />
    <actuatorvel name="right_wrist_02_v" actuator="right_wrist_02" />
    <actuatorfrc name="right_wrist_02_f" actuator="right_wrist_02" noise="0.001" />
    <framequat name="orientation" objtype="site" noise="0.001" objname="imu" />
    <gyro name="angular-velocity" site="imu" noise="0.005" cutoff="34.9" />
  </sensor>
</mujoco>