<mujoco model="kbot-v2">
  <default>
    <joint limited="true" damping="0.01" armature="0.01" frictionloss="0.01" />
    <geom condim="4" contype="1" conaffinity="15" friction="0.9 0.2 0.2" solref="0.001 2" />
    <motor ctrllimited="true" />
    <equality solref="0.001 2" />
    <default class="visualgeom">
      <geom material="visualgeom" condim="1" contype="0" conaffinity="0" />
    </default>
  </default>

  <compiler angle="radian" meshdir="meshes" eulerseq="zyx" autolimits="true" />

  <asset>
    <texture name="texplane" type="2d" builtin="checker" rgb1=".0 .0 .0" rgb2=".8 .8 .8" width="100" height="100" />
    <material name="matplane" reflectance="0." texture="texplane" texrepeat="1 1" texuniform="true" />
    <material name="KB-B-102B_TORSO_BOTTOM_material" rgba="0.61568627 0.81176471 0.92941176 1" />
    <material name="KB-D-102R_R_Hip_Yoke_Drive_material" rgba="0.2627451 0.28235294 0.30196078 1" />
    <material name="KB-D-102L_L_Hip_Yoke_Drive_material" rgba="0.2627451 0.28235294 0.30196078 1" />
    <material name="imu_material" rgba="0.61568627 0.81176471 0.92941176 1" />
    <material name="KB-C-101R_R_Shoulder_Drive_material" rgba="0.61568627 0.81176471 0.92941176 1" />
    <material name="KB-C-101L_ShldYokeROLL_material" rgba="0.61568627 0.81176471 0.92941176 1" />
    <material name="RS03_material_3" rgba="0.61568627 0.81176471 0.92941176 1" />
    <material name="RS03_material_4" rgba="0.61568627 0.81176471 0.92941176 1" />
    <material name="RS03_material_5" rgba="0.61568627 0.81176471 0.92941176 1" />
    <material name="RS03_material_6" rgba="0.61568627 0.81176471 0.92941176 1" />
    <material name="KB-D-301R_R_Femur_Lower_Drive_material" rgba="0.43921569 0.4745098 0.50196078 1" />
    <material name="R_Bicep_Lower_Drive_material" rgba="0.76470588 0.54509804 0.80392157 1" />
    <material name="KB-D-301L_L_Femur_Lower_Drive_material" rgba="0.43921569 0.4745098 0.50196078 1" />
    <material name="L_Bicep_Lower_Drive_material" rgba="0.76470588 0.54509804 0.80392157 1" />
    <material name="KB-D-401R_R_Shin_Drive_material" rgba="0.34901961 0.37647059 0.4 1" />
    <material name="R_Forearm_Upper_Structural_material" rgba="0.61568627 0.81176471 0.92941176 1" />
    <material name="KB-D-501R_R_LEG-FOOT_material" rgba="0.97254902 0.52941176 0.0039215686 1" />
    <material name="KB-D-401L_L_Shin_Drive_material" rgba="0.34901961 0.37647059 0.4 1" />
    <material name="L_Forearm_Upper_Drive_material" rgba="0.61568627 0.81176471 0.92941176 1" />
    <material name="KB-D-501L_L_LEG-FOOT_material" rgba="0.97254902 0.52941176 0.0039215686 1" />
    <material name="KB-C-501X_Bayonet_Adapter_Hard_Stop_material" rgba="0.91764706 0.91764706 0.91764706 1" />
    <material name="KB-C-501X_Bayonet_Adapter_Hard_Stop_material_2" rgba="0.91764706 0.91764706 0.91764706 1" />
    <material name="default_material" rgba="0.7 0.7 0.7 1" />
    <mesh name="KB-B-102B_TORSO_BOTTOM_collision.stl" file="KB-B-102B_TORSO_BOTTOM_collision.stl" />
    <mesh name="KB-B-102B_TORSO_BOTTOM.stl" file="KB-B-102B_TORSO_BOTTOM.stl" />
    <mesh name="KB-D-102R_R_Hip_Yoke_Drive.stl" file="KB-D-102R_R_Hip_Yoke_Drive.stl" />
    <mesh name="RS03_3_collision.stl" file="RS03_3_collision.stl" />
    <mesh name="RS03_3.stl" file="RS03_3.stl" />
    <mesh name="KB-D-301R_R_Femur_Lower_Drive_collision.stl" file="KB-D-301R_R_Femur_Lower_Drive_collision.stl" />
    <mesh name="KB-D-301R_R_Femur_Lower_Drive.stl" file="KB-D-301R_R_Femur_Lower_Drive.stl" />
    <mesh name="KB-D-401R_R_Shin_Drive_collision.stl" file="KB-D-401R_R_Shin_Drive_collision.stl" />
    <mesh name="KB-D-401R_R_Shin_Drive.stl" file="KB-D-401R_R_Shin_Drive.stl" />
    <mesh name="KB-D-501R_R_LEG-FOOT.convex.stl" file="KB-D-501R_R_LEG-FOOT.convex.stl" />
    <mesh name="KB-D-501R_R_LEG-FOOT.stl" file="KB-D-501R_R_LEG-FOOT.stl" />
    <mesh name="KB-D-102L_L_Hip_Yoke_Drive.stl" file="KB-D-102L_L_Hip_Yoke_Drive.stl" />
    <mesh name="RS03_4_collision.stl" file="RS03_4_collision.stl" />
    <mesh name="RS03_4.stl" file="RS03_4.stl" />
    <mesh name="KB-D-301L_L_Femur_Lower_Drive_collision.stl" file="KB-D-301L_L_Femur_Lower_Drive_collision.stl" />
    <mesh name="KB-D-301L_L_Femur_Lower_Drive.stl" file="KB-D-301L_L_Femur_Lower_Drive.stl" />
    <mesh name="KB-D-401L_L_Shin_Drive_collision.stl" file="KB-D-401L_L_Shin_Drive_collision.stl" />
    <mesh name="KB-D-401L_L_Shin_Drive.stl" file="KB-D-401L_L_Shin_Drive.stl" />
    <mesh name="KB-D-501L_L_LEG-FOOT.convex.stl" file="KB-D-501L_L_LEG-FOOT.convex.stl" />
    <mesh name="KB-D-501L_L_LEG-FOOT.stl" file="KB-D-501L_L_LEG-FOOT.stl" />
    <mesh name="imu.stl" file="imu.stl" />
    <mesh name="KB-C-101R_R_Shoulder_Drive.stl" file="KB-C-101R_R_Shoulder_Drive.stl" />
    <mesh name="RS03_5_collision.stl" file="RS03_5_collision.stl" />
    <mesh name="RS03_5.stl" file="RS03_5.stl" />
    <mesh name="R_Bicep_Lower_Drive_collision.stl" file="R_Bicep_Lower_Drive_collision.stl" />
    <mesh name="R_Bicep_Lower_Drive.stl" file="R_Bicep_Lower_Drive.stl" />
    <mesh name="R_Forearm_Upper_Structural_collision.stl" file="R_Forearm_Upper_Structural_collision.stl" />
    <mesh name="R_Forearm_Upper_Structural.stl" file="R_Forearm_Upper_Structural.stl" />
    <mesh name="KB-C-501X_Bayonet_Adapter_Hard_Stop.convex.stl" file="KB-C-501X_Bayonet_Adapter_Hard_Stop.convex.stl" />
    <mesh name="KB-C-501X_Bayonet_Adapter_Hard_Stop.stl" file="KB-C-501X_Bayonet_Adapter_Hard_Stop.stl" />
    <mesh name="KB-C-101L_ShldYokeROLL.stl" file="KB-C-101L_ShldYokeROLL.stl" />
    <mesh name="RS03_6_collision.stl" file="RS03_6_collision.stl" />
    <mesh name="RS03_6.stl" file="RS03_6.stl" />
    <mesh name="L_Bicep_Lower_Drive_collision.stl" file="L_Bicep_Lower_Drive_collision.stl" />
    <mesh name="L_Bicep_Lower_Drive.stl" file="L_Bicep_Lower_Drive.stl" />
    <mesh name="L_Forearm_Upper_Drive_collision.stl" file="L_Forearm_Upper_Drive_collision.stl" />
    <mesh name="L_Forearm_Upper_Drive.stl" file="L_Forearm_Upper_Drive.stl" />
    <mesh name="KB-C-501X_Bayonet_Adapter_Hard_Stop_2.convex.stl" file="KB-C-501X_Bayonet_Adapter_Hard_Stop_2.convex.stl" />
    <mesh name="KB-C-501X_Bayonet_Adapter_Hard_Stop_2.stl" file="KB-C-501X_Bayonet_Adapter_Hard_Stop_2.stl" />
  </asset>

  <worldbody>
    <light directional="true" diffuse="0.4 0.4 0.4" specular="0.1 0.1 0.1" pos="0 0 5.0" dir="0 0 -1" castshadow="false" />
    <light directional="true" diffuse="0.6 0.6 0.6" specular="0.2 0.2 0.2" pos="0 0 4" dir="0 0 -1" />
    <geom name="ground" type="plane" pos="0 0 0" size="10 10 0.001" quat="1 0 0 0" material="matplane" condim="3" conaffinity="15" />
    <body name="base" pos="0.00000000 0.00000000 0.80124348" quat="1 0 0 0">
      <freejoint name="floating_base" />
      <body name="KB-B-102B_TORSO_BOTTOM" pos="0.0 0.0 -0.001" quat="0.0007963267107332633 0.0 0.0 0.9999996829318346">
        <inertial pos="0.0003782656637492197 0.0026708360136527445 0.1600861519363398" quat="1.0 0.0 0.0 0.0" mass="15.456196869999996" diaginertia="0.6144236576682701 0.6513734713020699 0.07488731286920623" />
        <geom name="KB-B-102B_TORSO_BOTTOM_collision_0" pos="0 0 0" quat="1.0 0.0 0.0 0.0" type="mesh" mesh="KB-B-102B_TORSO_BOTTOM_collision.stl" rgba="0 0 0 0" />
        <geom name="KB-B-102B_TORSO_BOTTOM_visual" pos="0 0 0" quat="1.0 0.0 0.0 0.0" material="KB-B-102B_TORSO_BOTTOM_material" type="mesh" mesh="KB-B-102B_TORSO_BOTTOM.stl" />
        <body name="KB-D-102R_R_Hip_Yoke_Drive" pos="0.04804799199999996 -0.0007372588564082805 -0.07299347712820414" quat="0.49999997499999965 0.500000001794897 -0.500000011602551 -0.5000000116025513">
          <joint name="right_hip_pitch_04" type="hinge" range="-1.9198622 1.5707963" axis="0 0 1" />
          <inertial pos="-0.00518705193700639 -0.002373719838251741 -0.03915745987700441" quat="1.0 0.0 0.0 0.0" mass="0.7105343159999999" diaginertia="0.0012846056614709512 0.0015499048649316174 0.0017294271620225273" />
          <geom name="KB-D-102R_R_Hip_Yoke_Drive_visual" pos="0 0 0" quat="1.0 0.0 0.0 0.0" material="KB-D-102R_R_Hip_Yoke_Drive_material" type="mesh" mesh="KB-D-102R_R_Hip_Yoke_Drive.stl" />
          <body name="RS03_3" pos="-0.02825 -0.03 -0.0710000000267949" quat="0.7071067906599741 0.0 -0.707106771713121 0.0">
            <joint name="right_hip_roll_03" type="hinge" range="-2.6179939 0.20943951" axis="0 0 1" />
            <inertial pos="-0.0006771898283941686 -0.0582557273766471 -0.02828850020246948" quat="1.0 0.0 0.0 0.0" mass="2.5903163030000003" diaginertia="0.011063347679976337 0.0038037668340952352 0.011579821564733453" />
            <geom name="RS03_3_collision_0" pos="0 0 0" quat="1.0 0.0 0.0 0.0" type="mesh" mesh="RS03_3_collision.stl" rgba="0 0 0 0" />
            <geom name="RS03_3_visual" pos="0 0 0" quat="1.0 0.0 0.0 0.0" material="RS03_material_3" type="mesh" mesh="RS03_3.stl" />
            <body name="KB-D-301R_R_Femur_Lower_Drive" pos="0.0 -0.14275 -0.0297999999732051" quat="0.7071067906599741 0.707106771713121 0.0 0.0">
              <joint name="right_hip_yaw_02" type="hinge" range="-1.5707963 1.9198622" axis="0 0 -1" />
              <inertial pos="0.00013858062495375275 -0.010511168723892824 0.16247356818486833" quat="1.0 0.0 0.0 0.0" mass="2.556833893" diaginertia="0.018025570314963765 0.016368281312503202 0.004728526690542313" />
              <geom name="KB-D-301R_R_Femur_Lower_Drive_collision_0" pos="0 0 0" quat="1.0 0.0 0.0 0.0" type="mesh" mesh="KB-D-301R_R_Femur_Lower_Drive_collision.stl" rgba="0 0 0 0" />
              <geom name="KB-D-301R_R_Femur_Lower_Drive_visual" pos="0 0 0" quat="1.0 0.0 0.0 0.0" material="KB-D-301R_R_Femur_Lower_Drive_material" type="mesh" mesh="KB-D-301R_R_Femur_Lower_Drive.stl" />
              <body name="KB-D-401R_R_Shin_Drive" pos="0.02059999707935614 -0.02099999737725783 0.21199999817878992" quat="0.5000000344734256 0.5000000021291254 -0.49999997892402115 -0.49999998447342586">
                <joint name="left_knee_04" type="hinge" range="-2.6703538 0" axis="0 0 1" />
                <inertial pos="-0.026271134321132848 0.09758948179643992 0.02046254186557558" quat="1.0 0.0 0.0 0.0" mass="2.0622413400000004" diaginertia="0.018159448746640505 0.0038004776595966347 0.01785348023026493" />
                <geom name="KB-D-401R_R_Shin_Drive_collision_0" pos="0 0 0" quat="1.0 0.0 0.0 0.0" type="mesh" mesh="KB-D-401R_R_Shin_Drive_collision.stl" rgba="0 0 0 0" />
                <geom name="KB-D-401R_R_Shin_Drive_visual" pos="0 0 0" quat="1.0 0.0 0.0 0.0" material="KB-D-401R_R_Shin_Drive_material" type="mesh" mesh="KB-D-401R_R_Shin_Drive.stl" />
                <body name="KB-D-501R_R_LEG-FOOT" pos="-0.0313 0.2924999999535898 0.005999999999999999" quat="-2.3205103333142417e-08 0.9999999999999998 0.0 -0.0">
                  <joint name="left_ankle_02" type="hinge" range="-0.29670597 0.78539816" axis="0 0 1" />
                  <inertial pos="-0.013264634594717278 -0.028577942366742486 -0.011944334277895376" quat="1.0 0.0 0.0 0.0" mass="0.49274711000000004" diaginertia="0.00028345862075299837 0.0015602847602564514 0.0014852253016744811" />
                  <geom name="KB-D-501R_R_LEG-FOOT_collision_0" pos="0 0 0" quat="1.0 0.0 0.0 0.0" type="mesh" mesh="KB-D-501R_R_LEG-FOOT.convex.stl" rgba="0 0 0 0" />
                  <geom name="KB-D-501R_R_LEG-FOOT_visual" pos="0 0 0" quat="1.0 0.0 0.0 0.0" material="KB-D-501R_R_LEG-FOOT_material" type="mesh" mesh="KB-D-501R_R_LEG-FOOT.stl" />
                </body>
              </body>
            </body>
          </body>
        </body>
        <body name="KB-D-102L_L_Hip_Yoke_Drive" pos="-0.048048021999999996 -0.0007372570000000047 -0.07299347927179586" quat="0.5000000133974482 -0.4999999866025516 0.4999999999999999 -0.4999999999999999">
          <joint name="left_hip_pitch_04" type="hinge" range="-1.5707963 1.9198622" axis="0 0 1" />
          <inertial pos="-0.005269236736187477 0.0024332109371640754 -0.039157406265559025" quat="1.0 0.0 0.0 0.0" mass="0.710534346" diaginertia="0.0012869651899179624 0.0015439607861880997 0.0017258416243540707" />
          <geom name="KB-D-102L_L_Hip_Yoke_Drive_visual" pos="0 0 0" quat="1.0 0.0 0.0 0.0" material="KB-D-102L_L_Hip_Yoke_Drive_material" type="mesh" mesh="KB-D-102L_L_Hip_Yoke_Drive.stl" />
          <body name="RS03_4" pos="-0.028250000000000004 0.029999999953589793 -0.0709999999732051" quat="-1.64084861448314e-08 0.707106790659974 -1.6408485705167716e-08 -0.7071067717131209">
            <joint name="left_hip_roll_03" type="hinge" range="-0.20943951 2.6179939" axis="0 0 1" />
            <inertial pos="0.0006767801077187306 -0.05825706087927863 -0.028289463890326716" quat="1.0 0.0 0.0 0.0" mass="2.590428564" diaginertia="0.011063775523078797 0.00380414415674446 0.011580096572929934" />
            <geom name="RS03_4_collision_0" pos="0 0 0" quat="1.0 0.0 0.0 0.0" type="mesh" mesh="RS03_4_collision.stl" rgba="0 0 0 0" />
            <geom name="RS03_4_visual" pos="0 0 0" quat="1.0 0.0 0.0 0.0" material="RS03_material_4" type="mesh" mesh="RS03_4.stl" />
            <body name="KB-D-301L_L_Femur_Lower_Drive" pos="0.0 -0.14275000000000002 -0.0297999999732051" quat="0.7071067906599741 0.707106771713121 0.0 0.0">
              <joint name="left_hip_yaw_" type="hinge" range="-1.5707963 1.9198622" axis="0 0 -1" />
              <inertial pos="-0.00013851960764557286 -0.010510826872415776 0.1624762514749413" quat="1.0 0.0 0.0 0.0" mass="2.5567669129999997" diaginertia="0.018024794914299758 0.016367389347675666 0.004728344166477157" />
              <geom name="KB-D-301L_L_Femur_Lower_Drive_collision_0" pos="0 0 0" quat="1.0 0.0 0.0 0.0" type="mesh" mesh="KB-D-301L_L_Femur_Lower_Drive_collision.stl" rgba="0 0 0 0" />
              <geom name="KB-D-301L_L_Femur_Lower_Drive_visual" pos="0 0 0" quat="1.0 0.0 0.0 0.0" material="KB-D-301L_L_Femur_Lower_Drive_material" type="mesh" mesh="KB-D-301L_L_Femur_Lower_Drive.stl" />
              <body name="KB-D-401L_L_Shin_Drive" pos="-0.02059999595397059 -0.020999998909925658 0.21199999817878992" quat="0.5000000112683232 -0.49999997892402176 0.500000002129125 -0.5000000076785294">
                <joint name="right_knee_04" type="hinge" range="0 2.6703538" axis="0 0 1" />
                <inertial pos="-0.026127567283860474 -0.09759272580605333 0.02019484301225384" quat="1.0 0.0 0.0 0.0" mass="2.062098443" diaginertia="0.018129915712165132 0.0037884644914203086 0.01786986766558831" />
                <geom name="KB-D-401L_L_Shin_Drive_collision_0" pos="0 0 0" quat="1.0 0.0 0.0 0.0" type="mesh" mesh="KB-D-401L_L_Shin_Drive_collision.stl" rgba="0 0 0 0" />
                <geom name="KB-D-401L_L_Shin_Drive_visual" pos="0 0 0" quat="1.0 0.0 0.0 0.0" material="KB-D-401L_L_Shin_Drive_material" type="mesh" mesh="KB-D-401L_L_Shin_Drive.stl" />
                <body name="KB-D-501L_L_LEG-FOOT" pos="-0.0313 -0.2925 0.006" quat="1.0 0.0 0.0 0.0">
                  <joint name="right_ankle_02" type="hinge" range="-0.29670597 0.78539816" axis="0 0 -1" />
                  <inertial pos="-0.013264629288447597 -0.028577941761324492 0.011944320235142284" quat="1.0 0.0 0.0 0.0" mass="0.49274759" diaginertia="0.00028345878071963943 0.0015602852574658024 0.0014852257414326982" />
                  <geom name="KB-D-501L_L_LEG-FOOT_collision_0" pos="0 0 0" quat="1.0 0.0 0.0 0.0" type="mesh" mesh="KB-D-501L_L_LEG-FOOT.convex.stl" rgba="0 0 0 0" />
                  <geom name="KB-D-501L_L_LEG-FOOT_visual" pos="0 0 0" quat="1.0 0.0 0.0 0.0" material="KB-D-501L_L_LEG-FOOT_material" type="mesh" mesh="KB-D-501L_L_LEG-FOOT.stl" />
                </body>
              </body>
            </body>
          </body>
        </body>
        <body name="KB-C-101R_R_Shoulder_Drive" pos="0.1259499752752948 -0.0007372607282038752 0.3375065238332571" quat="0.4999999905265728 0.4999999728708734 -0.5000000460759765 -0.4999999905265743">
          <joint name="left_shoulder_pitch_03" type="hinge" range="-1.9198622 3.4906585" axis="0 0 1" />
          <inertial pos="-0.0049628393686060365 0.0033444089602305623 -0.044528158616558317" quat="1.0 0.0 0.0 0.0" mass="0.5450769340000001" diaginertia="0.0009463345633721918 0.001367831779393941 0.0011886349434901396" />
          <geom name="KB-C-101R_R_Shoulder_Drive_visual" pos="0 0 0" quat="1.0 0.0 0.0 0.0" material="KB-C-101R_R_Shoulder_Drive_material" type="mesh" mesh="KB-C-101R_R_Shoulder_Drive.stl" />
          <body name="RS03_5" pos="-0.02425 0.0 -0.0750000000267949" quat="0.7071067906599741 0.0 -0.707106771713121 0.0">
            <joint name="left_shoulder_roll_03" type="hinge" range="-1.4835299 0.48869219" axis="0 0 1" />
            <inertial pos="-0.0055335420515801705 -0.044203985461663695 -0.0297112802863472" quat="1.0 0.0 0.0 0.0" mass="1.861434012" diaginertia="0.007688888113351309 0.002130291592508498 0.0082354913293496" />
            <geom name="RS03_5_collision_0" pos="0 0 0" quat="1.0 0.0 0.0 0.0" type="mesh" mesh="RS03_5_collision.stl" rgba="0 0 0 0" />
            <geom name="RS03_5_visual" pos="0 0 0" quat="1.0 0.0 0.0 0.0" material="RS03_material_5" type="mesh" mesh="RS03_5.stl" />
            <body name="R_Bicep_Lower_Drive" pos="-0.013 -0.14199999871210736 -0.03025020675723656" quat="0.7071068234769445 -0.707106738896148 0.0 0.0">
              <joint name="left_shoulder_yaw_02" type="hinge" range="-1.7453293 1.7453293" axis="0 0 1" />
              <inertial pos="0.0017411616388135823 -0.0031280919212400083 -0.09610515410729122" quat="1.0 0.0 0.0 0.0" mass="0.8639227300000001" diaginertia="0.003003535191347657 0.0027890615217899565 0.0008941286732271809" />
              <geom name="R_Bicep_Lower_Drive_collision_0" pos="0 0 0" quat="1.0 0.0 0.0 0.0" type="mesh" mesh="R_Bicep_Lower_Drive_collision.stl" rgba="0 0 0 0" />
              <geom name="R_Bicep_Lower_Drive_visual" pos="0 0 0" quat="1.0 0.0 0.0 0.0" material="R_Bicep_Lower_Drive_material" type="mesh" mesh="R_Bicep_Lower_Drive.stl" />
              <body name="R_Forearm_Upper_Structural" pos="0.01849999579319584 -0.010000000495705515 -0.13699999839332602" quat="0.49999999052657385 -0.5000000228708746 -0.4999999960759779 0.499999990526573">
                <joint name="left_elbow_02" type="hinge" range="0 2.5307274" axis="0 0 1" />
                <inertial pos="0.01609026283073225 0.05904894315785105 0.014469685328960948" quat="1.0 0.0 0.0 0.0" mass="0.67694019" diaginertia="0.0013931469503859005 0.0006896925851535309 0.0013834881101174952" />
                <geom name="R_Forearm_Upper_Structural_collision_0" pos="0 0 0" quat="1.0 0.0 0.0 0.0" type="mesh" mesh="R_Forearm_Upper_Structural_collision.stl" rgba="0 0 0 0" />
                <geom name="R_Forearm_Upper_Structural_visual" pos="0 0 0" quat="1.0 0.0 0.0 0.0" material="R_Forearm_Upper_Structural_material" type="mesh" mesh="R_Forearm_Upper_Structural.stl" />
                <body name="KB-C-501X_Bayonet_Adapter_Hard_Stop" pos="0.0173500001 0.1065 0.018000000000000002" quat="0.49999998839744764 0.5000000249999996 0.49999997500000004 -0.500000011602551">
                  <joint name="left_wrist_02" type="hinge" range="-1.7453293 1.7453293" axis="0 0 1" />
                  <inertial pos="-0.0025711914314223063 3.507378735866289e-06 -0.03937061937464469" quat="1.0 0.0 0.0 0.0" mass="0.571798567" diaginertia="0.0007498682482275756 0.0007200954438047711 0.0005812785366945832" />
                  <geom name="KB-C-501X_Bayonet_Adapter_Hard_Stop_collision_0" pos="0 0 0" quat="1.0 0.0 0.0 0.0" type="mesh" mesh="KB-C-501X_Bayonet_Adapter_Hard_Stop.convex.stl" rgba="0 0 0 0" />
                  <geom name="KB-C-501X_Bayonet_Adapter_Hard_Stop_visual" pos="0 0 0" quat="1.0 0.0 0.0 0.0" material="KB-C-501X_Bayonet_Adapter_Hard_Stop_material" type="mesh" mesh="KB-C-501X_Bayonet_Adapter_Hard_Stop.stl" />
                </body>
              </body>
            </body>
          </body>
        </body>
        <body name="KB-C-101L_ShldYokeROLL" pos="-0.12595002472470498 -0.0007372554994855747 0.33750651981315316" quat="0.5000000021291257 -0.5000000112683226 -0.4999999844734263 0.5000000021291249">
          <joint name="right_shoulder_pitch_03" type="hinge" range="-1.9198622 3.4906585" axis="0 0 -1" />
          <inertial pos="0.005189448927249461 -0.0033442798689079967 0.04452743143713337" quat="1.0 0.0 0.0 0.0" mass="0.5450985750000001" diaginertia="0.000946335188923059 0.0013557994541993801 0.0011766514582420865" />
          <geom name="KB-C-101L_ShldYokeROLL_visual" pos="0 0 0" quat="1.0 0.0 0.0 0.0" material="KB-C-101L_ShldYokeROLL_material" type="mesh" mesh="KB-C-101L_ShldYokeROLL.stl" />
          <body name="RS03_6" pos="0.024250000000000004 -4.6410206666284833e-11 0.0750000000267949" quat="-1.64084861448314e-08 0.707106790659974 1.6408485705167716e-08 0.7071067717131209">
            <joint name="right_shoulder_roll_03" type="hinge" range="-0.48869219 1.4835299" axis="0 0 1" />
            <inertial pos="0.0055336383154532395 -0.04421963407414807 -0.02971155273896361" quat="1.0 0.0 0.0 0.0" mass="1.86146043" diaginertia="0.0076944721487699815 0.0021303412001471567 0.008241064234760254" />
            <geom name="RS03_6_collision_0" pos="0 0 0" quat="1.0 0.0 0.0 0.0" type="mesh" mesh="RS03_6_collision.stl" rgba="0 0 0 0" />
            <geom name="RS03_6_visual" pos="0 0 0" quat="1.0 0.0 0.0 0.0" material="RS03_material_6" type="mesh" mesh="RS03_6.stl" />
            <body name="L_Bicep_Lower_Drive" pos="0.012999999999999998 -0.14199999871210692 -0.030250213106331834" quat="0.7071068209385776 -0.7071067414345152 0.0 0.0">
              <joint name="right_shoulder_yaw_02" type="hinge" range="-1.7453293 1.7453293" axis="0 0 1" />
              <inertial pos="-0.0017237583507574645 -0.0031233771479135383 -0.09608773793030688" quat="1.0 0.0 0.0 0.0" mass="0.86429688" diaginertia="0.0030043829770575164 0.002790430770809992 0.0008948845399314567" />
              <geom name="L_Bicep_Lower_Drive_collision_0" pos="0 0 0" quat="1.0 0.0 0.0 0.0" type="mesh" mesh="L_Bicep_Lower_Drive_collision.stl" rgba="0 0 0 0" />
              <geom name="L_Bicep_Lower_Drive_visual" pos="0 0 0" quat="1.0 0.0 0.0 0.0" material="L_Bicep_Lower_Drive_material" type="mesh" mesh="L_Bicep_Lower_Drive.stl" />
              <body name="L_Forearm_Upper_Drive" pos="-0.01849999632909377 -0.009999999504294511 -0.13700000085641692" quat="0.5000000228708743 0.4999999905265736 0.49999999052657323 0.499999996075978">
                <joint name="right_elbow_02" type="hinge" range="-2.5307274 0" axis="0 0 1" />
                <inertial pos="0.01608930935043711 -0.05904931390894698 0.014469293934365857" quat="1.0 0.0 0.0 0.0" mass="0.67693693" diaginertia="0.001393125691692786 0.0006896973269303887 0.001383494899296689" />
                <geom name="L_Forearm_Upper_Drive_collision_0" pos="0 0 0" quat="1.0 0.0 0.0 0.0" type="mesh" mesh="L_Forearm_Upper_Drive_collision.stl" rgba="0 0 0 0" />
                <geom name="L_Forearm_Upper_Drive_visual" pos="0 0 0" quat="1.0 0.0 0.0 0.0" material="L_Forearm_Upper_Drive_material" type="mesh" mesh="L_Forearm_Upper_Drive.stl" />
                <body name="KB-C-501X_Bayonet_Adapter_Hard_Stop_2" pos="0.01734999994641021 -0.1065 0.018" quat="0.5000000133974483 0.4999999999999999 -0.49999999999999983 0.4999999866025518">
                  <joint name="right_wrist_02" type="hinge" range="-1.7453293 1.7453293" axis="0 0 -1" />
                  <inertial pos="0.0025711916062907607 3.5075700050043644e-06 0.039370619375316135" quat="1.0 0.0 0.0 0.0" mass="0.571798567" diaginertia="0.0007498682482197616 0.000720095439536694 0.0005812785324046792" />
                  <geom name="KB-C-501X_Bayonet_Adapter_Hard_Stop_2_collision_0" pos="0 0 0" quat="1.0 0.0 0.0 0.0" type="mesh" mesh="KB-C-501X_Bayonet_Adapter_Hard_Stop_2.convex.stl" rgba="0 0 0 0" />
                  <geom name="KB-C-501X_Bayonet_Adapter_Hard_Stop_2_visual" pos="0 0 0" quat="1.0 0.0 0.0 0.0" material="KB-C-501X_Bayonet_Adapter_Hard_Stop_material_2" type="mesh" mesh="KB-C-501X_Bayonet_Adapter_Hard_Stop_2.stl" />
                </body>
              </body>
            </body>
          </body>
        </body>
        <site name="imu" pos="-4.488159466925432e-05 0.009977114961696199 0.40030576959807607" quat="0.002413754053603244 -0.99999708689144 4.996751611903313e-08 -1.351809638104972e-08" />
      </body>
      <site name="base_site" pos="0 0 0" quat="1 0 0 0" />
    </body>
  </worldbody>

  <actuator>
    <position name="right_hip_pitch_04_ctrl" joint="right_hip_pitch_04" kp="250.00000000" kv="30.00000000" forcerange="-120.00000000 120.00000000" forcelimited="true" ctrlrange="-1.9198622 1.5707963" ctrllimited="true" />
    <position name="right_hip_roll_03_ctrl" joint="right_hip_roll_03" kp="150.00000000" kv="8.00000000" forcerange="-60.00000000 60.00000000" forcelimited="true" ctrlrange="-2.6179939 0.20943951" ctrllimited="true" />
    <position name="right_hip_yaw_02_ctrl" joint="right_hip_yaw_02" kp="20.00000000" kv="2.00000000" forcerange="-17.00000000 17.00000000" forcelimited="true" ctrlrange="-1.5707963 1.9198622" ctrllimited="true" />
    <position name="left_knee_04_ctrl" joint="left_knee_04" kp="200.00000000" kv="8.00000000" forcerange="-120.00000000 120.00000000" forcelimited="true" ctrlrange="-2.6703538 0.0" ctrllimited="true" />
    <position name="left_ankle_02_ctrl" joint="left_ankle_02" kp="80.00000000" kv="10.00000000" forcerange="-17.00000000 17.00000000" forcelimited="true" ctrlrange="-0.29670597 0.78539816" ctrllimited="true" />
    <position name="left_hip_pitch_04_ctrl" joint="left_hip_pitch_04" kp="250.00000000" kv="30.00000000" forcerange="-120.00000000 120.00000000" forcelimited="true" ctrlrange="-1.5707963 1.9198622" ctrllimited="true" />
    <position name="left_hip_roll_03_ctrl" joint="left_hip_roll_03" kp="150.00000000" kv="8.00000000" forcerange="-60.00000000 60.00000000" forcelimited="true" ctrlrange="-0.20943951 2.6179939" ctrllimited="true" />
    <position name="left_hip_yaw__ctrl" joint="left_hip_yaw_" kp="20.00000000" kv="2.00000000" forcerange="-17.00000000 17.00000000" forcelimited="true" ctrlrange="-1.5707963 1.9198622" ctrllimited="true" />
    <position name="right_knee_04_ctrl" joint="right_knee_04" kp="200.00000000" kv="8.00000000" forcerange="-120.00000000 120.00000000" forcelimited="true" ctrlrange="0.0 2.6703538" ctrllimited="true" />
    <position name="right_ankle_02_ctrl" joint="right_ankle_02" kp="80.00000000" kv="10.00000000" forcerange="-17.00000000 17.00000000" forcelimited="true" ctrlrange="-0.29670597 0.78539816" ctrllimited="true" />
    <position name="left_shoulder_pitch_03_ctrl" joint="left_shoulder_pitch_03" kp="150.00000000" kv="8.00000000" forcerange="-60.00000000 60.00000000" forcelimited="true" ctrlrange="-1.9198622 3.4906585" ctrllimited="true" />
    <position name="left_shoulder_roll_03_ctrl" joint="left_shoulder_roll_03" kp="150.00000000" kv="8.00000000" forcerange="-60.00000000 60.00000000" forcelimited="true" ctrlrange="-1.4835299 0.48869219" ctrllimited="true" />
    <position name="left_shoulder_yaw_02_ctrl" joint="left_shoulder_yaw_02" kp="50.00000000" kv="5.00000000" forcerange="-17.00000000 17.00000000" forcelimited="true" ctrlrange="-1.7453293 1.7453293" ctrllimited="true" />
    <position name="left_elbow_02_ctrl" joint="left_elbow_02" kp="50.00000000" kv="5.00000000" forcerange="-17.00000000 17.00000000" forcelimited="true" ctrlrange="0.0 2.5307274" ctrllimited="true" />
    <position name="left_wrist_02_ctrl" joint="left_wrist_02" kp="20.00000000" kv="2.00000000" forcerange="-17.00000000 17.00000000" forcelimited="true" ctrlrange="-1.7453293 1.7453293" ctrllimited="true" />
    <position name="right_shoulder_pitch_03_ctrl" joint="right_shoulder_pitch_03" kp="150.00000000" kv="8.00000000" forcerange="-60.00000000 60.00000000" forcelimited="true" ctrlrange="-1.9198622 3.4906585" ctrllimited="true" />
    <position name="right_shoulder_roll_03_ctrl" joint="right_shoulder_roll_03" kp="150.00000000" kv="8.00000000" forcerange="-60.00000000 60.00000000" forcelimited="true" ctrlrange="-0.48869219 1.4835299" ctrllimited="true" />
    <position name="right_shoulder_yaw_02_ctrl" joint="right_shoulder_yaw_02" kp="50.00000000" kv="5.00000000" forcerange="-17.00000000 17.00000000" forcelimited="true" ctrlrange="-1.7453293 1.7453293" ctrllimited="true" />
    <position name="right_elbow_02_ctrl" joint="right_elbow_02" kp="50.00000000" kv="5.00000000" forcerange="-17.00000000 17.00000000" forcelimited="true" ctrlrange="-2.5307274 0.0" ctrllimited="true" />
    <position name="right_wrist_02_ctrl" joint="right_wrist_02" kp="20.00000000" kv="2.00000000" forcerange="-17.00000000 17.00000000" forcelimited="true" ctrlrange="-1.7453293 1.7453293" ctrllimited="true" />
  </actuator>

  <sensor>
    <accelerometer name="imu_acc" site="imu" noise="0.01" />
    <gyro name="imu_gyro" site="imu" noise="0.01" />
    <magnetometer name="imu_mag" site="imu" noise="0.05" />
    <framepos name="base_link_pos" objtype="site" objname="imu" />
    <framequat name="base_link_quat" objtype="site" objname="imu" />
    <framelinvel name="base_link_vel" objtype="site" objname="imu" />
    <frameangvel name="base_link_ang_vel" objtype="site" objname="imu" />
  </sensor>
</mujoco>